Workbook

Sheet Financials>
B2: Legend
B3: Hardcoded
B4: Formula
B5: Intersheet Links
B6: Intrasheet Links
B8: Note -
B9: All Hardcoded numbers are taken from the Company's 10K, 8K reports and trusted websites

Sheet Revenue
A2: # | B2: Particulars | C2: Unit | D2: Historical | H2: Forecast
D3: 2021 | E3: =D3+1 -> 2022 | F3: =E3+1 -> 2023 | G3: =F3+1 -> 2024 | H3: =G3+1 -> 2025 | I3: =H3+1 -> 2026 | J3: =I3+1 -> 2027 | K3: =J3+1 -> 2028 | L3: =K3+1 -> 2029
B5: Europe, Middle East & Africa | C5: $ | D5: 7193 | E5: 7523 | F5: 8078 | G5: 8122 | H5: =G5*(1+H8) -> 9391.9357 | I5: =H5*(1+I8) -> 10753.727 | J5: =I5*(1+J8) -> 12190.791 | K5: =J5*(1+K8) -> 13681.388 | L5: =K5*(1+L8) -> 15323.154
B6: Growth Rate % | E6: =E5/D5-1 -> 0.045877937 | F6: =F5/E5-1 -> 0.07377376 | G6: =G5/F5-1 -> 0.0054468928
B7: Add/Less: Inorganic growth 1 | D7: -0.01 | E7: 0.124 | F7: 0.12 | G7: 0.16
B8: Organic Growth % | E8: =E6+E7 -> 0.16987794 | F8: =F6+F7 -> 0.19377376 | G8: =G6+G7 -> 0.16544689 | H8: =G8-(($G$8-$L$8)/5) -> 0.15635751 | I8: =H8-(($G$8-$L$8)/4) -> 0.14499579 | J8: =I8-(($G$8-$L$8)/4) -> 0.13363407 | K8: =J8-(($G$8-$L$8)/4) -> 0.12227234 | L8: 0.12
B10: Latin America | D10: 4143 | E10: 4910 | F10: 5830 | G10: 6459 | H10: =G10*(1+H13) -> 7933.6684 | I10: =H10*(1+I13) -> 9589.6958 | J10: =I10*(1+J13) -> 11403.645 | K10: =J10*(1+K13) -> 13337.453 | L10: =K10*(1+L13) -> 15338.071
B11: Growth Rate % | E11: =E10/D10-1 -> 0.18513155 | F11: =F10/E10-1 -> 0.18737271 | G11: =G10/F10-1 -> 0.10789022
B12: Add/Less: Inorganic growth | E12: 0.06 | F12: 0.03 | G12: 0.14
B13: Organic Growth % | E13: =E11+E12 -> 0.24513155 | F13: =F11+F12 -> 0.21737271 | G13: =G11+G12 -> 0.24789022 | H13: =G13-(($G$13-$L$13)/5) -> 0.22831218 | I13: =H13-(($G$13-$L$13)/5) -> 0.20873413 | J13: =I13-(($G$13-$L$13)/5) -> 0.18915609 | K13: =J13-(($G$13-$L$13)/5) -> 0.16957804 | L13: 0.15
B15: North America | D15: 13190 | E15: 15674 | F15: 16774 | G15: 18649 | H15: =G15*(1+H18) -> 20577.756 | I15: =H15*(1+I18) -> 22534.044 | J15: =I15*(1+J18) -> 24488.017 | K15: =J15*(1+K18) -> 26406.801 | L15: =K15*(1+L18) -> 28255.277
B16: Growth Rate % | E16: =E15/D15-1 -> 0.18832449 | F16: =F15/E15-1 -> 0.070179916 | G16: =G15/F15-1 -> 0.11178014
B17: Add/Less: Inorganic growth | E17: -0.06 | F17: 0 | G17: 0
B18: Organic Growth % | E18: =E16+E17 -> 0.12832449 | F18: =F16+F17 -> 0.070179916 | G18: =G16+G17 -> 0.11178014 | H18: =G18-(($G$18-$L$18)/5) -> 0.10342411 | I18: =H18-(($G$18-$L$18)/5) -> 0.095068082 | J18: =I18-(($G$18-$L$18)/5) -> 0.086712054 | K18: =J18-(($G$18-$L$18)/5) -> 0.078356027 | L18: 0.07
B20: Asia Pacific | D20: 5291 | E20: 5445 | F20: 5455 | G20: 5546 | H20: =G20*(1+H23) -> 5830.7624 | I20: =H20*(1+I23) -> 6157.3386 | J20: =I20*(1+J23) -> 6530.9214 | K20: =J20*(1+K23) -> 6957.6282 | L20: =K20*(1+L23) -> 7444.6622
B21: Growth Rate % | E21: =E20/D20-1 -> 0.029106029 | F21: =F20/E20-1 -> 0.0018365473 | G21: =G20/F20-1 -> 0.016681943
B22: Add/Less: Inorganic growth | E22: 0.08 | F22: 0.04 | G22: 0.03
B23: Organic Growth % | E23: =E21+E22 -> 0.10910603 | F23: =F21+F22 -> 0.041836547 | G23: =G21+G22 -> 0.046681943 | H23: =G23-(($G$23-$L$23)/5) -> 0.051345555 | I23: =H23-(($G$23-$L$23)/5) -> 0.056009166 | J23: =I23-(($G$23-$L$23)/5) -> 0.060672777 | K23: =J23-(($G$23-$L$23)/5) -> 0.065336389 | L23: 0.07
B25: Global Ventures | D25: 2805 | E25: 2843 | F25: 3064 | G25: 3129 | H25: =G25*(1+H28) -> 3163.3291 | I25: =H25*(1+I28) -> 3228.9001 | J25: =I25*(1+J28) -> 3327.3352 | K25: =J25*(1+K28) -> 3461.2365 | L25: =K25*(1+L28) -> 3634.2983
B26: Growth Rate % | E26: =E25/D25-1 -> 0.013547237 | F26: =F25/E25-1 -> 0.077734787 | G26: =G25/F25-1 -> 0.021214099
B27: Add/Less: Inorganic growth | E27: 0.12 | F27: 0 | G27: -0.02
B28: Organic Growth % | E28: =E26+E27 -> 0.13354724 | F28: =F26+F27 -> 0.077734787 | G28: =G26+G27 -> 0.0012140992 | H28: =G28-(($G$28-$L$28)/5) -> 0.010971279 | I28: =H28-(($G$28-$L$28)/5) -> 0.02072846 | J28: =I28-(($G$28-$L$28)/5) -> 0.03048564 | K28: =J28-(($G$28-$L$28)/5) -> 0.04024282 | L28: 0.05
B30: Bottling Investments | D30: 7203 | E30: 7891 | F30: 7860 | G30: 6223 | H30: =G30*(1+H33) -> 6022.4483 | I30: =H30*(1+I33) -> 5571.9175 | J30: =I30*(1+J33) -> 5023.4443 | K30: =J30*(1+K33) -> 4679.3864 | L30: =K30*(1+L33) -> 4302.3303
B31: Growth Rate % | E31: =E30/D30-1 -> 0.095515757 | F31: =F30/E30-1 -> -0.0039285262 | G31: =G30/F30-1 -> -0.20826972
B32: Add/Less: Inorganic growth (only fx) 2 | G32: 0.02
B33: Organic Growth % 3 | E33: =E31+E32 -> 0.095515757 | F33: =F31+F32 -> -0.0039285262 | G33: =G31+G32 -> -0.18826972 | H33: =AVERAGE(E33:G33) -> -0.032227496 | I33: =AVERAGE(F33:H33) -> -0.074808581 | J33: =AVERAGE(G33:I33) -> -0.098435266 | K33: =AVERAGE(H33:J33) -> -0.068490448 | L33: =AVERAGE(I33:K33) -> -0.080578098 | M33: 4
B35: Corporate | D35: 85 | E35: 94 | F35: 126 | G35: 97 | H35: =G35*(1+H38) -> 103.98882 | I35: =H35*(1+I38) -> 110.30845 | J35: =I35*(1+J38) -> 106.72942 | K35: =J35*(1+K38) -> 110.30046 | L35: =K35*(1+L38) -> 112.57211
B36: Growth Rate % | E36: =E35/D35-1 -> 0.10588235 | F36: =F35/E35-1 -> 0.34042553 | G36: =G35/F35-1 -> -0.23015873
B37: Add/Less: Inorganic growth | E37: 0 | F37: 0 | G37: 0
B38: Organic Growth % | E38: =E36+E37 -> 0.10588235 | F38: =F36+F37 -> 0.34042553 | G38: =G36+G37 -> -0.23015873 | H38: =AVERAGE(E38:G38) -> 0.072049718 | I38: =AVERAGE(F38:H38) -> 0.060772173 | J38: =AVERAGE(G38:I38) -> -0.032445613 | K38: =AVERAGE(H38:J38) -> 0.03345876 | L38: =AVERAGE(I38:K38) -> 0.020595107
B40: Total Revenue before Eliminations | D40: =SUM(D5,D10,D15,D20,D25,D30,D35) -> 39910 | E40: =SUM(E5,E10,E15,E20,E25,E30,E35) -> 44380 | F40: =SUM(F5,F10,F15,F20,F25,F30,F35) -> 47187 | G40: =SUM(G5,G10,G15,G20,G25,G30,G35) -> 48225 | H40: =SUM(H5,H10,H15,H20,H25,H30,H35) -> 53023.889 | I40: =SUM(I5,I10,I15,I20,I25,I30,I35) -> 57945.931 | J40: =SUM(J5,J10,J15,J20,J25,J30,J35) -> 63070.884 | K40: =SUM(K5,K10,K15,K20,K25,K30,K35) -> 68634.193 | L40: =SUM(L5,L10,L15,L20,L25,L30,L35) -> 74410.365
B42: Eliminations | D42: -1255 | E42: -1376 | F42: -1433 | G42: -1164 | H42: =-H40*H43 -> -1511.3638 | I42: =-I40*I43 -> -1651.6589 | J42: =-J40*J43 -> -1797.7378 | K42: =-K40*K43 -> -1956.3113 | L42: =-L40*L43 -> -2120.9521
B43: Eliminations as a % of Revenue before Eliminations | D43: =-D42/D40 -> 0.031445753 | E43: =-E42/E40 -> 0.031004957 | F43: =-F42/F40 -> 0.030368534 | G43: =-G42/G40 -> 0.024136858 | H43: =AVERAGE($E$43:$G$43) -> 0.02850345 | I43: =AVERAGE($E$43:$G$43) -> 0.02850345 | J43: =AVERAGE($E$43:$G$43) -> 0.02850345 | K43: =AVERAGE($E$43:$G$43) -> 0.02850345 | L43: =AVERAGE($E$43:$G$43) -> 0.02850345
A45: # | B45: Total Consolidated Revenue | D45: =SUM(D5,D10,D15,D20,D25,D30,D35,D42) -> 38655 | E45: =SUM(E5,E10,E15,E20,E25,E30,E35,E42) -> 43004 | F45: =SUM(F5,F10,F15,F20,F25,F30,F35,F42) -> 45754 | G45: =SUM(G5,G10,G15,G20,G25,G30,G35,G42) -> 47061 | H45: =SUM(H5,H10,H15,H20,H25,H30,H35,H42) -> 51512.525 | I45: =SUM(I5,I10,I15,I20,I25,I30,I35,I42) -> 56294.272 | J45: =SUM(J5,J10,J15,J20,J25,J30,J35,J42) -> 61273.146 | K45: =SUM(K5,K10,K15,K20,K25,K30,K35,K42) -> 66677.882 | L45: =SUM(L5,L10,L15,L20,L25,L30,L35,L42) -> 72289.413
B47: Notes -
B48: 1. Inorganic growth refers to the growth of revenue of the segment contributed by factors such as; forex currency fluctuations, restructuring activities in the form of acquisitions and divestments
B49: 2. Acquisitions and divestments factor is excluded in the inorganic growth adjustment for bottling investments segment due to historical data showing Coca-Cola's strategy of being asset-light in this segment by adopting a franchise model where bottling of their products is undertaken by bottling partners
B50: 3. In addition to the above note, the operating assumption is that Coca-Cola will further divest in this segment to reduce CapEx and focus on its brand value and hence the revenue from their own bottling investments will reduce in the forecasted years
B51: 4. %Figures which are more volatile/uncertain in terms of their historical changes are forecasted by applying a moving average in this financial model

Sheet P&L
A3: # | B3: Particulars | C3: Unit | D3: Historical | H3: Forecast
D4: 2021 | E4: =D4+1 -> 2022 | F4: =E4+1 -> 2023 | G4: =F4+1 -> 2024 | H4: =G4+1 -> 2025 | I4: =H4+1 -> 2026 | J4: =I4+1 -> 2027 | K4: =J4+1 -> 2028 | L4: =K4+1 -> 2029
B6: Net Operating Revenues | C6: $ | D6: =Revenue!D45 -> 38655 | E6: =Revenue!E45 -> 43004 | F6: =Revenue!F45 -> 45754 | G6: =Revenue!G45 -> 47061 | H6: =Revenue!H45 -> 51512.525 | I6: =Revenue!I45 -> 56294.272 | J6: =Revenue!J45 -> 61273.146 | K6: =Revenue!K45 -> 66677.882 | L6: =Revenue!L45 -> 72289.413
B7: Add/Less: Extraordinary Items 1 | D7: 3 | E7: 42 | F7: 30 | G7: -164 | H7: 0 | I7: 0 | J7: 0 | K7: 0 | L7: 0
B8: Normalised Revenue | D8: =SUM(D6:D7) -> 38658 | E8: =SUM(E6:E7) -> 43046 | F8: =SUM(F6:F7) -> 45784 | G8: =SUM(G6:G7) -> 46897 | H8: =SUM(H6:H7) -> 51512.525 | I8: =SUM(I6:I7) -> 56294.272 | J8: =SUM(J6:J7) -> 61273.146 | K8: =SUM(K6:K7) -> 66677.882 | L8: =SUM(L6:L7) -> 72289.413
B10: COGS | D10: 15357 | E10: 18000 | F10: 18520 | G10: 18324
B11: Add/Less: Extraordinary Items | D11: 53 | E11: -183 | F11: -55 | G11: -70
B12: Normalised COGS | D12: =SUM(D10:D11) -> 15410 | E12: =SUM(E10:E11) -> 17817 | F12: =SUM(F10:F11) -> 18465 | G12: =SUM(G10:G11) -> 18254 | H12: =H8-H13 -> 20670.337 | I12: =I8-I13 -> 22589.1 | J12: =J8-J13 -> 24586.963 | K12: =K8-K13 -> 26755.712 | L12: =L8-L13 -> 29007.441
B13: Normalised Gross Profit | D13: =D8-D12 -> 23248 | E13: =E8-E12 -> 25229 | F13: =F8-F12 -> 27319 | G13: =G8-G12 -> 28643 | H13: =H8*H55 -> 30842.188 | I13: =I8*I55 -> 33705.172 | J13: =J8*J55 -> 36686.183 | K13: =K8*K55 -> 39922.17 | L13: =L8*L55 -> 43281.972
B15: SG&A | D15: 12144 | E15: 12880 | F15: 13972 | G15: 14582
B16: Add/Less: Extraordinary Items | D16: -5 | E16: 4 | F16: 11 | G16: -24
B17: Normalised SG&A | D17: =SUM(D15:D16) -> 12139 | E17: =SUM(E15:E16) -> 12884 | F17: =SUM(F15:F16) -> 13983 | G17: =SUM(G15:G16) -> 14558 | H17: =H56*H8 -> 15829.221 | I17: =I56*I8 -> 17298.598 | J17: =J56*J8 -> 18828.55 | K17: =K56*K8 -> 20489.365 | L17: =L56*L8 -> 22213.725
B19: Other OpEx | D19: 846 | E19: 1215 | F19: 1951 | G19: 4163
B20: Add/Less: Extraordinary Items | D20: -846 | E20: -1215 | F20: -1951 | G20: -4163
B21: Normalised OpEx | D21: =SUM(D19:D20) -> 0 | E21: =SUM(E19:E20) -> 0 | F21: =SUM(F19:F20) -> 0 | G21: =SUM(G19:G20) -> 0 | H21: =G21 -> 0 | I21: =H21 -> 0 | J21: =I21 -> 0 | K21: =J21 -> 0 | L21: =K21 -> 0
B22: Normalised EBIT | D22: =D13-D17-D21 -> 11109 | E22: =E13-E17-E21 -> 12345 | F22: =F13-F17-F21 -> 13336 | G22: =G13-G17-G21 -> 14085 | H22: =H13-H17-H21 -> 15012.967 | I22: =I13-I17-I21 -> 16406.574 | J22: =J13-J17-J21 -> 17857.633 | K22: =K13-K17-K21 -> 19432.805 | L22: =L13-L17-L21 -> 21068.247
B24: Interest income | D24: 276 | E24: 449 | F24: 907 | G24: 988
B25: Add/Less: Extraordinary Items | D25: 0 | E25: 0 | F25: 0 | G25: 0
B26: Normalised Interest income | D26: =SUM(D24:D25) -> 276 | E26: =SUM(E24:E25) -> 449 | F26: =SUM(F24:F25) -> 907 | G26: =SUM(G24:G25) -> 988 | H26: =H66*AVERAGE('Balance Sheet'!G6:H6) -> 853.0267 | I26: =I66*AVERAGE('Balance Sheet'!H6:I6) -> 916.18101 | J26: =J66*AVERAGE('Balance Sheet'!I6:J6) -> 1056.4943 | K26: =K66*AVERAGE('Balance Sheet'!J6:K6) -> 1132.9978 | L26: =L66*AVERAGE('Balance Sheet'!K6:L6) -> 1114.13
B28: Interest expense | D28: 1597 | E28: 882 | F28: 1527 | G28: 1656
B29: Add/Less: Extraordinary Items | D29: -821 | E29: 24 | F29: 25 | G29: 25
B30: Normalised Interest expense | D30: =SUM(D28:D29) -> 776 | E30: =SUM(E28:E29) -> 906 | F30: =SUM(F28:F29) -> 1552 | G30: =SUM(G28:G29) -> 1681 | H30: =SUM(Debt!D24,Debt!D20) -> 1519.1822 | I30: =SUM(Debt!E24,Debt!E20) -> 1438.8716 | J30: =SUM(Debt!F24,Debt!F20) -> 1308.3587 | K30: =SUM(Debt!G24,Debt!G20) -> 1149.076 | L30: =SUM(Debt!H24,Debt!H20) -> 946.68897
B32: Equity income (loss) — net | D32: 1438 | E32: 1472 | F32: 1691 | G32: 1770
B33: Add/Less: Extraordinary Items | D33: 13 | E33: 34 | F33: 159 | G33: 92
B34: Normalised Equity income (loss) — net | D34: =SUM(D32:D33) -> 1451 | E34: =SUM(E32:E33) -> 1506 | F34: =SUM(F32:F33) -> 1850 | G34: =SUM(G32:G33) -> 1862 | H34: =H59*H8 -> 1965.6055 | I34: =I59*I8 -> 2148.0665 | J34: =J59*J8 -> 2338.0495 | K34: =K59*K8 -> 2544.2824 | L34: =L59*L8 -> 2758.4061
B36: Other income (loss) — net | D36: 2000 | E36: -262 | F36: 570 | G36: 1992
B37: Add/Less: Extraordinary Items | D37: -1633 | E37: 245 | F37: -708 | G37: -1913
B38: Normalised Other income (loss) — net | D38: =SUM(D36:D37) -> 367 | E38: =SUM(E36:E37) -> -17 | F38: =SUM(F36:F37) -> -138 | G38: =SUM(G36:G37) -> 79 | H38: =AVERAGE(E38:G38) -> -25.333333 | I38: =AVERAGE(F38:H38) -> -28.111111 | J38: =AVERAGE(G38:I38) -> 8.5185185 | K38: =AVERAGE(H38:J38) -> -14.975309 | L38: =AVERAGE(I38:K38) -> -11.522634
B39: Normalised PBT | D39: =D22+D26-D30+D34+D38 -> 12427 | E39: =E22+E26-E30+E34+E38 -> 13377 | F39: =F22+F26-F30+F34+F38 -> 14403 | G39: =G22+G26-G30+G34+G38 -> 15333 | H39: =H22+H26-H30+H34+H38 -> 16287.084 | I39: =I22+I26-I30+I34+I38 -> 18003.839 | J39: =J22+J26-J30+J34+J38 -> 19952.336 | K39: =K22+K26-K30+K34+K38 -> 21946.034 | L39: =L22+L26-L30+L34+L38 -> 23982.572
B41: Income Taxes | D41: 2621 | E41: 2115 | F41: 2249 | G41: 2437
B42: Add/Less: Extraordinary Items | D42: -313 | E42: 430 | F42: 488 | G42: 415
B43: Normalised Income Taxes | D43: =SUM(D41:D42) -> 2308 | E43: =SUM(E41:E42) -> 2545 | F43: =SUM(F41:F42) -> 2737 | G43: =SUM(G41:G42) -> 2852 | H43: =H39*H58 -> 3062.0144 | I43: =I39*I58 -> 3384.7688 | J43: =J39*J58 -> 3751.0914 | K43: =K39*K58 -> 4125.9118 | L43: =L39*L58 -> 4508.7861
B44: Consolidated Net Income | D44: =D39-D43 -> 10119 | E44: =E39-E43 -> 10832 | F44: =F39-F43 -> 11666 | G44: =G39-G43 -> 12481 | H44: =H39-H43 -> 13225.07 | I44: =I39-I43 -> 14619.07 | J44: =J39-J43 -> 16201.245 | K44: =K39-K43 -> 17820.122 | L44: =L39-L43 -> 19473.785
B45: Less: Net income (loss) attributable to noncontrolling interests | D45: 33 | E45: 29 | F45: -11 | G45: 18 | H45: =H44*H61 -> 21.284842 | I45: =I44*I61 -> 23.528391 | J45: =J44*J61 -> 26.074792 | K45: =K44*K61 -> 28.680264 | L45: =L44*L61 -> 31.341721
B46: Net Income Attributable to Shareowners of The Coca-Cola Company | D46: =D44-D45 -> 10086 | E46: =E44-E45 -> 10803 | F46: =F44-F45 -> 11677 | G46: =G44-G45 -> 12463 | H46: =H44-H45 -> 13203.785 | I46: =I44-I45 -> 14595.542 | J46: =J44-J45 -> 16175.17 | K46: =K44-K45 -> 17791.442 | L46: =L44-L45 -> 19442.444
B48: Diluted EPS | D48: =D46/D49 -> 2.3239631 | E48: =E46/E49 -> 2.4834483 | F48: =F46/F49 -> 2.6911731 | G48: =G46/G49 -> 2.8849537 | H48: =H46/H49 -> 3.0564317 | I48: =I46/I49 -> 3.3785977 | J48: =J46/J49 -> 3.7442523 | K48: =K46/K49 -> 4.1183894 | L48: =L46/L49 -> 4.5005657
B49: Average Shares Outstanding — Diluted | D49: 4340 | E49: 4350 | F49: 4339 | G49: 4320 | H49: =G49 -> 4320 | I49: =H49 -> 4320 | J49: =I49 -> 4320 | K49: =J49 -> 4320 | L49: =K49 -> 4320
B51: Dividend Per Share | D51: 1.68 | E51: 1.76 | F51: 1.84 | G51: 1.94 | H51: =H52*H48 -> 2.133278 | I51: =I52*I48 -> 2.4443231 | J51: =J52*J48 -> 2.8043768 | K51: =K52*K48 -> 3.1896551 | L51: =L52*L48 -> 3.6004525
B52: Dividend Payout Ratio 2 | D52: =D51/D48 -> 0.72290303 | E52: =E51/E48 -> 0.70869203 | F52: =F51/F48 -> 0.68371671 | G52: =G51/G48 -> 0.67245447 | H52: =G52+($L$52-$G$52)/5 -> 0.69796357 | I52: =H52+($L$52-$G$52)/5 -> 0.72347268 | J52: =I52+($L$52-$G$52)/5 -> 0.74898179 | K52: =J52+($L$52-$G$52)/5 -> 0.77449089 | L52: 0.8
A54: # | B54: Workings
...

Sheet Balance Sheet
B2: Particulars | C2: Unit | D2: Historical | H2: Forecast
A3: # | D3: 2021 | E3: =D3+1 -> 2022 | F3: =E3+1 -> 2023 | G3: =F3+1 -> 2024 | H3: =G3+1 -> 2025 | I3: =H3+1 -> 2026 | J3: =I3+1 -> 2027 | K3: =J3+1 -> 2028 | L3: =K3+1 -> 2029
B4: Assets
B5: Current Assets | C5: $
B6: Cash and cash equivalents | D6: 9684 | E6: 9519 | F6: 9366 | G6: 10828 | H6: =CFS!D42 -> 10438.348 | I6: =CFS!E42 -> 12402.466 | J6: =CFS!F42 -> 13936.423 | K6: =CFS!G42 -> 14309.735 | L6: =CFS!H42 -> 13466.039
B7: Short-term investments | D7: 1242 | E7: 1043 | F7: 2997 | G7: 2020 | H7: =G7 -> 2020 | I7: =H7 -> 2020 | J7: =I7 -> 2020 | K7: =J7 -> 2020 | L7: =K7 -> 2020
B8: Total Cash, Cash Equivalents and Short-Term Investments | D8: =SUM(D6:D7) -> 10926 | E8: =SUM(E6:E7) -> 10562 | F8: =SUM(F6:F7) -> 12363 | G8: =SUM(G6:G7) -> 12848 | H8: =SUM(H6:H7) -> 12458.348 | I8: =SUM(I6:I7) -> 14422.466 | J8: =SUM(J6:J7) -> 15956.423 | K8: =SUM(K6:K7) -> 16329.735 | L8: =SUM(L6:L7) -> 15486.039
B9: Marketable securities | D9: 1699 | E9: 1069 | F9: 1300 | G9: 1723 | H9: =G9 -> 1723 | I9: =H9 -> 1723 | J9: =I9 -> 1723 | K9: =J9 -> 1723 | L9: =K9 -> 1723
B10: Trade accounts receivable | D10: 3512 | E10: 3487 | F10: 3410 | G10: 3569 | H10: =H46 -> 3728.9509 | I10: =I46 -> 3866.0355 | J10: =J46 -> 3980.4094 | K10: =K46 -> 4083.8861 | L10: =L46 -> 4159.1169
B11: Inventories | D11: 3414 | E11: 4233 | F11: 4424 | G11: 4728 | H11: =H50 -> 5415.7089 | I11: =I50 -> 5986.0228 | J11: =J50 -> 6589.0173 | K11: =K50 -> 7250.2743 | L11: =L50 -> 7947.2441
B12: Prepaid expenses and other current assets | D12: 2994 | E12: 3240 | F12: 5235 | G12: 3129 | H12: =H54 -> 3480.6509 | I12: =I54 -> 3803.7488 | J12: =J54 -> 4140.1665 | K12: =K54 -> 4505.3592 | L12: =L54 -> 4884.5248
B13: Total Current Assets | D13: =D8+SUM(D9:D12) -> 22545 | E13: =E8+SUM(E9:E12) -> 22591 | F13: =F8+SUM(F9:F12) -> 26732 | G13: =G8+SUM(G9:G12) -> 25997 | H13: =H8+SUM(H9:H12) -> 26806.659 | I13: =I8+SUM(I9:I12) -> 29801.273 | J13: =J8+SUM(J9:J12) -> 32389.016 | K13: =K8+SUM(K9:K12) -> 33892.254 | L13: =L8+SUM(L9:L12) -> 34199.925
B14: Equity method investments | D14: 17598 | E14: 18264 | F14: 19671 | G14: 18087 | H14: =G14 -> 18087 | I14: =H14 -> 18087 | J14: =I14 -> 18087 | K14: =J14 -> 18087 | L14: =K14 -> 18087
B15: Deferred income tax assets | D15: 2129 | E15: 1746 | F15: 1561 | G15: 1319 | H15: =G15 -> 1319 | I15: =H15 -> 1319 | J15: =I15 -> 1319 | K15: =J15 -> 1319 | L15: =K15 -> 1319
B16: Property, plant and equipment — net | D16: 9920 | E16: 9841 | F16: 9236 | G16: 10303 | H16: =CapEx!H10 -> 10058.688 | I16: =CapEx!I10 -> 9754.0669 | J16: =CapEx!J10 -> 9403.1293 | K16: =CapEx!K10 -> 9082.1235 | L16: =CapEx!L10 -> 8708.6428
B17: Trademarks with indefinite lives | D17: 14465 | E17: 14214 | F17: 14349 | G17: 13301 | H17: =G17 -> 13301 | I17: =H17 -> 13301 | J17: =I17 -> 13301 | K17: =J17 -> 13301 | L17: =K17 -> 13301
B18: Goodwill | D18: 19363 | E18: 18782 | F18: 18358 | G18: 18139 | H18: =G18 -> 18139 | I18: =H18 -> 18139 | J18: =I18 -> 18139 | K18: =J18 -> 18139 | L18: =K18 -> 18139
B19: Other noncurrent assets | D19: =D40 -> 8334 | E19: =E40 -> 7325 | F19: 7796 | G19: 13403 | H19: =CapEx!H15 -> 13349 | I19: =CapEx!I15 -> 13307 | J19: =CapEx!J15 -> 13265 | K19: =CapEx!K15 -> 13231 | L19: =CapEx!L15 -> 13197
B20: Total Assets | D20: =SUM(D13:D19) -> 94354 | E20: =SUM(E13:E19) -> 92763 | F20: =SUM(F13:F19) -> 97703 | G20: =SUM(G13:G19) -> 100549 | H20: =SUM(H13:H19) -> 101060.35 | I20: =SUM(I13:I19) -> 103708.34 | J20: =SUM(J13:J19) -> 105903.15 | K20: =SUM(K13:K19) -> 107051.38 | L20: =SUM(L13:L19) -> 106951.57
B22: Liabilities and Equity
B23: Current Liabilities
B24: Accounts payable and accrued expenses | D24: 14619 | E24: 15749 | F24: 15485 | G24: 21715 | H24: =H58 -> 19951.095 | I24: =I58 -> 21803.093 | J24: =J58 -> 23731.439 | K24: =K58 -> 25824.725 | L24: =L58 -> 27998.103
B25: Loans and notes payable | D25: 3307 | E25: 2373 | F25: 4557 | G25: 1499 | H25: =Debt!D17 -> 2893.8059 | I25: =Debt!E17 -> 2422.5484 | J25: =Debt!F17 -> 2301.812 | K25: =Debt!G17 -> 1944.7573 | L25: =Debt!H17 -> 1494.9771
B26: Current maturities of long-term debt | D26: 1338 | E26: 399 | F26: 1960 | G26: 648 | H26: =-Debt!E8 -> 1803 | I26: =-Debt!F8 -> 5064 | J26: =-Debt!G8 -> 2786 | K26: =-Debt!H8 -> 2684 | L26: =K26 -> 2684
B27: Accrued income taxes | D27: 686 | E27: 1203 | F27: 1569 | G27: 1387 | H27: =H61 -> 1400.4883 | I27: =I61 -> 1548.1081 | J27: =J61 -> 1715.6548 | K27: =K61 -> 1887.0882 | L27: =L61 -> 2062.2053
B28: Total Current Liabilities | D28: =SUM(D24:D27) -> 19950 | E28: =SUM(E24:E27) -> 19724 | F28: =SUM(F24:F27) -> 23571 | G28: =SUM(G24:G27) -> 25249 | H28: =SUM(H24:H27) -> 26048.39 | I28: =SUM(I24:I27) -> 30837.75 | J28: =SUM(J24:J27) -> 30534.906 | K28: =SUM(K24:K27) -> 32340.57 | L28: =SUM(L24:L27) -> 34239.285
B29: Long-term debt | D29: 38116 | E29: 36377 | F29: 35547 | G29: 42375 | H29: =Debt!D11 -> 38077.648 | I29: =Debt!E11 -> 31876.687 | J29: =Debt!F11 -> 30287.999 | K29: =Debt!G11 -> 25589.755 | L29: =Debt!H11 -> 19671.399
B30: Other noncurrent liabilities | D30: 8607 | E30: 7922 | F30: 8466 | G30: 4084 | H30: =G30 -> 4084 | I30: =H30 -> 4084 | J30: =I30 -> 4084 | K30: =J30 -> 4084 | L30: =K30 -> 4084
B31: Deferred income tax liabilities | D31: 2821 | E31: 2914 | F31: 2639 | G31: 2469 | H31: =G31 -> 2469 | I31: =H31 -> 2469 | J31: =I31 -> 2469 | K31: =J31 -> 2469 | L31: =K31 -> 2469
B32: Equity Attributable to Shareowners of The Coca-Cola Company | D32: 22999 | E32: 24105 | F32: 25941 | G32: 24856 | H32: =G32+'P&L'!H46-'P&L'!H65 -> 28844.024 | I32: =H32+'P&L'!I46-'P&L'!I65 -> 32880.09 | J32: =I32+'P&L'!J46-'P&L'!J65 -> 36940.352 | K32: =J32+'P&L'!K46-'P&L'!K65 -> 40952.485 | L32: =K32+'P&L'!L46-'P&L'!L65 -> 44840.973
B33: Equity attributable to noncontrolling interests | D33: 1861 | E33: 1721 | F33: 1539 | G33: 1516 | H33: =G33+'P&L'!H45 -> 1537.2848 | I33: =H33+'P&L'!I45 -> 1560.8132 | J33: =I33+'P&L'!J45 -> 1586.888 | K33: =J33+'P&L'!K45 -> 1615.5683 | L33: =K33+'P&L'!L45 -> 1646.91
B34: Total Equity | D34: =SUM(D32:D33) -> 24860 | E34: =SUM(E32:E33) -> 25826 | F34: =SUM(F32:F33) -> 27480 | G34: =SUM(G32:G33) -> 26372 | H34: =SUM(H32:H33) -> 30381.309 | I34: =SUM(I32:I33) -> 34440.903 | J34: =SUM(J32:J33) -> 38527.24 | K34: =SUM(K32:K33) -> 42568.053 | L34: =SUM(L32:L33) -> 46487.883
B35: Total Liabilities and Equity | D35: =SUM(D34,D28:D31) -> 94354 | E35: =SUM(E34,E28:E31) -> 92763 | F35: =SUM(F34,F28:F31) -> 97703 | G35: =SUM(G34,G28:G31) -> 100549 | H35: =SUM(H34,H28:H31) -> 101060.35 | I35: =SUM(I34,I28:I31) -> 103708.34 | J35: =SUM(J34,J28:J31) -> 105903.15 | K35: =SUM(K34,K28:K31) -> 107051.38 | L35: =SUM(L34,L28:L31) -> 106951.57
B37: Difference | D37: =D20-D35 -> 0 | E37: =E20-E35 -> 0 | F37: =F20-F35 -> 0 | G37: =G20-G35 -> 0 | H37: =H20-H35 -> 0 | I37: =I20-I35 -> 0 | J37: =J20-J35 -> 0 | K37: =K20-K35 -> 0 | L37: =L20-L35 -> 0
B39: Workings -
B40: Other Non-Current Assets | D40: =SUM(D41:D43) -> 8334 | E40: =SUM(E41:E43) -> 7325
B41: Other investments | D41: 818 | E41: 501 | F41: 118 | G41: =F41 -> 118 | H41: =G41 -> 118 | I41: =H41 -> 118 | J41: =I41 -> 118 | K41: =J41 -> 118 | L41: =K41 -> 118
B42: Other noncurrent assets | D42: 6731 | E42: 6189
B43: Other intangible assets | D43: 785 | E43: 635
B45: Current assets
...

Sheet CFS
B2: Particulars | C2: Unit | D2: Forecast
A3: # | D3: 2025 | E3: =D3+1 -> 2026 | F3: =E3+1 -> 2027 | G3: =F3+1 -> 2028 | H3: =G3+1 -> 2029
B5: Cash Flow from Operations - | C5: $
B6: Consolidated Net Income | D6: ='P&L'!H44 -> 13225.07 | E6: ='P&L'!I44 -> 14619.07 | F6: ='P&L'!J44 -> 16201.245 | G6: ='P&L'!K44 -> 17820.122 | H6: ='P&L'!L44 -> 19473.785
B8: Add/Less: Non Cash/Non Operating items -
B9: Depreciation and Amortization | D9: =CapEx!H19 -> 1130.8021 | E9: =CapEx!I19 -> 1161.1629 | F9: =CapEx!J19 -> 1203.3066 | G9: =CapEx!K19 -> 1241.4044 | H9: =CapEx!L19 -> 1287.1522
B10: Interest Income | D10: =-'P&L'!H26 -> -853.0267 | E10: =-'P&L'!I26 -> -916.18101 | F10: =-'P&L'!J26 -> -1056.4943 | G10: =-'P&L'!K26 -> -1132.9978 | H10: =-'P&L'!L26 -> -1114.13
B11: Interest Expense | D11: ='P&L'!H30 -> 1519.1822 | E11: ='P&L'!I30 -> 1438.8716 | F11: ='P&L'!J30 -> 1308.3587 | G11: ='P&L'!K30 -> 1149.076 | H11: ='P&L'!L30 -> 946.68897
B12: Equity Income | D12: =-'P&L'!H34 -> -1965.6055 | E12: =-'P&L'!I34 -> -2148.0665 | F12: =-'P&L'!J34 -> -2338.0495 | G12: =-'P&L'!K34 -> -2544.2824 | H12: =-'P&L'!L34 -> -2758.4061
B13: Other Income | D13: =-'P&L'!H38 -> 25.333333 | E13: =-'P&L'!I38 -> 28.111111 | F13: =-'P&L'!J38 -> -8.5185185 | G13: =-'P&L'!K38 -> 14.975309 | H13: =-'P&L'!L38 -> 11.522634
B14: Cash Flow from Operations before Working Capital Changes | D14: =SUM(D6:D13) -> 13081.755 | E14: =SUM(E6:E13) -> 14182.968 | F14: =SUM(F6:F13) -> 15309.848 | G14: =SUM(G6:G13) -> 16548.298 | H14: =SUM(H6:H13) -> 17846.613
B16: Changes in Working Capital -
B17: Trade accounts receivable | D17: =-('Balance Sheet'!H10-'Balance Sheet'!G10) -> -159.95093 | E17: =-('Balance Sheet'!I10-'Balance Sheet'!H10) -> -137.08457 | F17: =-('Balance Sheet'!J10-'Balance Sheet'!I10) -> -114.37392 | G17: =-('Balance Sheet'!K10-'Balance Sheet'!J10) -> -103.47663 | H17: =-('Balance Sheet'!L10-'Balance Sheet'!K10) -> -75.230865
B18: Inventories | D18: =-('Balance Sheet'!H11-'Balance Sheet'!G11) -> -687.70889 | E18: =-('Balance Sheet'!I11-'Balance Sheet'!H11) -> -570.31393 | F18: =-('Balance Sheet'!J11-'Balance Sheet'!I11) -> -602.99453 | G18: =-('Balance Sheet'!K11-'Balance Sheet'!J11) -> -661.25692 | H18: =-('Balance Sheet'!L11-'Balance Sheet'!K11) -> -696.96981
B19: Prepaid expenses and other current assets | D19: =-('Balance Sheet'!H12-'Balance Sheet'!G12) -> -351.65087 | E19: =-('Balance Sheet'!I12-'Balance Sheet'!H12) -> -323.09796 | F19: =-('Balance Sheet'!J12-'Balance Sheet'!I12) -> -336.41762 | G19: =-('Balance Sheet'!K12-'Balance Sheet'!J12) -> -365.19271 | H19: =-('Balance Sheet'!L12-'Balance Sheet'!K12) -> -379.16566
B20: Accounts payable and accrued expenses | D20: ='Balance Sheet'!H24-'Balance Sheet'!G24 -> -1763.9047 | E20: ='Balance Sheet'!I24-'Balance Sheet'!H24 -> 1851.998 | F20: ='Balance Sheet'!J24-'Balance Sheet'!I24 -> 1928.3462 | G20: ='Balance Sheet'!K24-'Balance Sheet'!J24 -> 2093.2851 | H20: ='Balance Sheet'!L24-'Balance Sheet'!K24 -> 2173.3781
B21: Accrued Income Taxes | D21: =('Balance Sheet'!H27-'Balance Sheet'!G27) -> 13.488344 | E21: =('Balance Sheet'!I27-'Balance Sheet'!H27) -> 147.61977 | F21: =('Balance Sheet'!J27-'Balance Sheet'!I27) -> 167.5467 | G21: =('Balance Sheet'!K27-'Balance Sheet'!J27) -> 171.43344 | H21: =('Balance Sheet'!L27-'Balance Sheet'!K27) -> 175.1171
B22: Cash Generated from Operations | D22: =SUM(D14:D21) -> 10132.028 | E22: =SUM(E14:E21) -> 15152.09 | F22: =SUM(F14:F21) -> 16351.955 | G22: =SUM(G14:G21) -> 17683.09 | H22: =SUM(H14:H21) -> 19043.742
B24: Cash from Investing -
B25: Net Purchase/Sale of PPE | D25: =-CapEx!H7 -> -832.49001 | E25: =-CapEx!I7 -> -814.54187 | F25: =-CapEx!J7 -> -810.3691 | G25: =-CapEx!K7 -> -886.39859 | H25: =-CapEx!L7 -> -879.67146
B26: Purchase of Intangibles | D26: 0 | E26: 0 | F26: 0 | G26: 0 | H26: 0
B27: Interest Income | D27: =-D10 -> 853.0267 | E27: =-E10 -> 916.18101 | F27: =-F10 -> 1056.4943 | G27: =-G10 -> 1132.9978 | H27: =-H10 -> 1114.13
B28: Equity Income | D28: ='P&L'!H34 -> 1965.6055 | E28: ='P&L'!I34 -> 2148.0665 | F28: ='P&L'!J34 -> 2338.0495 | G28: ='P&L'!K34 -> 2544.2824 | H28: ='P&L'!L34 -> 2758.4061
B29: Other Income | D29: ='P&L'!H38 -> -25.333333 | E29: ='P&L'!I38 -> -28.111111 | F29: ='P&L'!J38 -> 8.5185185 | G29: ='P&L'!K38 -> -14.975309 | H29: ='P&L'!L38 -> -11.522634
B30: Cash Generated from Investing | D30: =SUM(D25:D29) -> 1960.8088 | E30: =SUM(E25:E29) -> 2221.5945 | F30: =SUM(F25:F29) -> 2592.6932 | G30: =SUM(G25:G29) -> 2775.9063 | H30: =SUM(H25:H29) -> 2981.3421
B32: Cash Flow from Financing
B33: Debt Raised | D33: =SUM(Debt!D7,Debt!D15) -> -1099.5457 | E33: =SUM(Debt!E7,Debt!E15) -> -1136.9612 | F33: =SUM(Debt!F7,Debt!F15) -> 1197.3115 | G33: =SUM(Debt!G7,Debt!G15) -> -2014.244 | H33: =SUM(Debt!H7,Debt!H15) -> -3234.3553
B34: Debt Repaid | D34: =Debt!D8+Debt!D16 -> -648 | E34: =Debt!E8+Debt!E16 -> -2274.2575 | F34: =Debt!F8+Debt!F16 -> -5184.7363 | G34: =Debt!G8+Debt!G16 -> -3143.0548 | H34: =Debt!H8+Debt!H16 -> -3133.7802
B35: Interest Expense | D35: =-D11 -> -1519.1822 | E35: =-E11 -> -1438.8716 | F35: =-F11 -> -1308.3587 | G35: =-G11 -> -1149.076 | H35: =-H11 -> -946.68897
B36: Dividend | D36: =-'P&L'!H65 -> -9215.7609 | E36: =-'P&L'!I65 -> -10559.476 | F36: =-'P&L'!J65 -> -12114.908 | G36: =-'P&L'!K65 -> -13779.31 | H36: =-'P&L'!L65 -> -15553.955
B37: Cash Generated from Financing | D37: =SUM(D33:D36) -> -12482.489 | E37: =SUM(E33:E36) -> -15409.566 | F37: =SUM(F33:F36) -> -17410.691 | G37: =SUM(G33:G36) -> -20085.685 | H37: =SUM(H33:H36) -> -22868.779
B39: Total Cash Generated during the Year | D39: =SUM(D37,D30,D22) -> -389.65183 | E39: =SUM(E37,E30,E22) -> 1964.118 | F39: =SUM(F37,F30,F22) -> 1533.9566 | G39: =SUM(G37,G30,G22) -> 373.31176 | H39: =SUM(H37,H30,H22) -> -843.69541
B41: Add: Opening Balance of Cash and Cash Equivalents | D41: ='Balance Sheet'!G6 -> 10828 | E41: =D42 -> 10438.348 | F41: =E42 -> 12402.466 | G41: =F42 -> 13936.423 | H41: =G42 -> 14309.735
A42: # | B42: Closing Balance | D42: =SUM(D39:D41) -> 10438.348 | E42: =SUM(E39:E41) -> 12402.466 | F42: =SUM(F39:F41) -> 13936.423 | G42: =SUM(G39:G41) -> 14309.735 | H42: =SUM(H39:H41) -> 13466.039

Sheet Supporting Schedules>

Sheet CapEx
A2: # | B2: Particulars | C2: Unit | D2: Historical | H2: Forecast
D3: 2021 | E3: =D3+1 -> 2022 | F3: =E3+1 -> 2023 | G3: =F3+1 -> 2024 | H3: =G3+1 -> 2025 | I3: =H3+1 -> 2026 | J3: =I3+1 -> 2027 | K3: =J3+1 -> 2028 | L3: =K3+1 -> 2029
B5: Propert, Plant and Equipment - | C5: $
B6: Opening Gross Block | D6: 19700 | E6: =D8 -> 18862 | F6: =E8 -> 19075 | G6: =F8 -> 18469 | H6: =G8 -> 19873 | I6: =H8 -> 20705.49 | J6: =I8 -> 21520.032 | K6: =J8 -> 22330.401 | L6: =K8 -> 23216.8
B7: Add: Net Purchases/Sale | D7: =D8-D6 -> -838 | E7: =E8-E6 -> 213 | F7: =F8-F6 -> -606 | G7: =G8-G6 -> 1404 | H7: =H8-H6 -> 832.49001 | I7: =I8-I6 -> 814.54187 | J7: =J8-J6 -> 810.3691 | K7: =K8-K6 -> 886.39859 | L7: =L8-L6 -> 879.67146
B8: Closing Gross Block | D8: 18862 | E8: 19075 | F8: 18469 | G8: 19873 | H8: ='P&L'!H8/CapEx!H21 -> 20705.49 | I8: ='P&L'!I8/CapEx!I21 -> 21520.032 | J8: ='P&L'!J8/CapEx!J21 -> 22330.401 | K8: ='P&L'!K8/CapEx!K21 -> 23216.8 | L8: ='P&L'!L8/CapEx!L21 -> 24096.471
B9: Less: Accumulated Depreciation | D9: 8942 | E9: 9234 | F9: 9233 | G9: 9570 | H9: =G9+H18 -> 10646.802 | I9: =H9+I18 -> 11765.965 | J9: =I9+J18 -> 12927.272 | K9: =J9+K18 -> 14134.676 | L9: =K9+L18 -> 15387.828
B10: Net Block | D10: =D8-D9 -> 9920 | E10: =E8-E9 -> 9841 | F10: =F8-F9 -> 9236 | G10: =G8-G9 -> 10303 | H10: =H8-H9 -> 10058.688 | I10: =I8-I9 -> 9754.0669 | J10: =J8-J9 -> 9403.1293 | K10: =K8-K9 -> 9082.1235 | L10: =L8-L9 -> 8708.6428
B12: Other Non-Current Assets -
B13: Opening Balance | H13: ='Balance Sheet'!G19 -> 13403 | I13: =H15 -> 13349 | J13: =I15 -> 13307 | K13: =J15 -> 13265 | L13: =K15 -> 13231
B14: Less: Amortization | H14: =-H22 -> -54 | I14: =-I22 -> -42 | J14: =-J22 -> -42 | K14: =-K22 -> -34 | L14: =-L22 -> -34
B15: Closing Balance | H15: =SUM(H13:H14) -> 13349 | I15: =SUM(I13:I14) -> 13307 | J15: =SUM(J13:J14) -> 13265 | K15: =SUM(K13:K14) -> 13231 | L15: =SUM(L13:L14) -> 13197
B18: Depreciation | D18: 1262 | E18: 1125 | F18: 1018 | G18: 997 | H18: =H8*H20 -> 1076.8021 | I18: =I8*I20 -> 1119.1629 | J18: =J8*J20 -> 1161.3066 | K18: =K8*K20 -> 1207.4044 | L18: =L8*L20 -> 1253.1522
B19: Depreciation & Amortization | D19: 1452 | E19: 1260 | F19: 1128 | G19: 1075 | H19: =H18+H22 -> 1130.8021 | I19: =I18+I22 -> 1161.1629 | J19: =J18+J22 -> 1203.3066 | K19: =K18+K22 -> 1241.4044 | L19: =L18+L22 -> 1287.1522
B20: Rate of Depreciation | D20: =D18/((D6+D8)/2) -> 0.065453037 | E20: =E18/((E6+E8)/2) -> 0.059308854 | F20: =F18/((F6+F8)/2) -> 0.054229704 | G20: =G18/((G6+G8)/2) -> 0.052005634 | H20: =G20 -> 0.052005634 | I20: =H20 -> 0.052005634 | J20: =I20 -> 0.052005634 | K20: =J20 -> 0.052005634 | L20: =K20 -> 0.052005634
B21: Fixed Asset Turnover Ratio | D21: ='P&L'!D8/CapEx!D8 -> 2.0495175 | E21: ='P&L'!E8/CapEx!E8 -> 2.256671 | F21: ='P&L'!F8/CapEx!F8 -> 2.4789648 | G21: ='P&L'!G8/CapEx!G8 -> 2.359835 | H21: =G21+(($L$21-$G$21)/5) -> 2.487868 | I21: =H21+(($L$21-$G$21)/5) -> 2.615901 | J21: =I21+(($L$21-$G$21)/5) -> 2.743934 | K21: =J21+(($L$21-$G$21)/5) -> 2.871967 | L21: 3
A22: # | B22: Amortization (Forecasted in FS 2023) 1 | H22: 54 | I22: 42 | J22: 42 | K22: 34 | L22: =K22 -> 34 | M22: 2
B24: Notes -
B25: 1. Amortization expense forecast figures not available in the 10K report for FY 24, hence FY 23 figs are taken
B26: 2. Amortization expense for the year 2029 not given in FY23 10K report and hence straight lined forecasted expense from FY2028

Sheet Debt
A2: # | B2: Particulars | C2: Unit | D2: Forecast
D3: 2025 | E3: =D3+1 -> 2026 | F3: =E3+1 -> 2027 | G3: =F3+1 -> 2028 | H3: =G3+1 -> 2029
B5: Long Term Debt - | C5: $
B6: Opening Balance | D6: 43023 | E6: =D9 -> 39880.648 | F6: =E9 -> 36940.687 | G6: =F9 -> 33073.999 | H6: =G9 -> 28273.755
B7: Add: Loan taken | D7: =D9-D6-D8 -> -2494.3517 | E7: =E9-E6-E8 -> -1136.9612 | F7: =F9-F6-F8 -> 1197.3115 | G7: =G9-G6-G8 -> -2014.244 | H7: =H9-H6-H8 -> -3234.3553
B8: Less: Loan repaid | D8: -648 | E8: -1803 | F8: -5064 | G8: -2786 | H8: -2684
B9: Total Debt | D9: =D25*'P&L'!H62 -> 39880.648 | E9: =E25*'P&L'!I62 -> 36940.687 | F9: =F25*'P&L'!J62 -> 33073.999 | G9: =G25*'P&L'!K62 -> 28273.755 | H9: =H25*'P&L'!L62 -> 22355.399
B10: Less: Current Maturities | D10: =E8 -> -1803 | E10: =F8 -> -5064 | F10: =G8 -> -2786 | G10: =H8 -> -2684 | H10: =G10 -> -2684
B11: Closing Balance | D11: =SUM(D9:D10) -> 38077.648 | E11: =SUM(E9:E10) -> 31876.687 | F11: =SUM(F9:F10) -> 30287.999 | G11: =SUM(G9:G10) -> 25589.755 | H11: =SUM(H9:H10) -> 19671.399
B13: Loans and Notes Payable -
B14: Opening Balance | D14: ='Balance Sheet'!G25 -> 1499 | E14: =D17 -> 2893.8059 | F14: =E17 -> 2422.5484 | G14: =F17 -> 2301.812 | H14: =G17 -> 1944.7573
B15: Add: Loan taken | D15: =IF(D17>D14,D17-D14,0) -> 1394.8059 | E15: =IF(E17>E14,E17-E14,0) -> 0 | F15: =IF(F17>F14,F17-F14,0) -> 0 | G15: =IF(G17>G14,G17-G14,0) -> 0 | H15: =IF(H17>H14,H17-H14,0) -> 0
B16: Less: Loan repaid | D16: =IF(D14>D17,-(D14-D17),0) -> 0 | E16: =IF(E14>E17,-(E14-E17),0) -> -471.25753 | F16: =IF(F14>F17,-(F14-F17),0) -> -120.73635 | G16: =IF(G14>G17,-(G14-G17),0) -> -357.05478 | H16: =IF(H14>H17,-(H14-H17),0) -> -449.78018
B17: Closing Balance | D17: =D21*D11 -> 2893.8059 | E17: =E21*E11 -> 2422.5484 | F17: =F21*F11 -> 2301.812 | G17: =G21*G11 -> 1944.7573 | H17: =H21*H11 -> 1494.9771
B19: Average Interest Rate | D19: 0.05 | E19: =D19 -> 0.05 | F19: =E19 -> 0.05 | G19: =F19 -> 0.05 | H19: =G19 -> 0.05
B20: Interest Expenses | D20: =D19*AVERAGE(D14,D17) -> 109.82015 | E20: =E19*AVERAGE(E14,E17) -> 132.90886 | F20: =F19*AVERAGE(F14,F17) -> 118.10901 | G20: =G19*AVERAGE(G14,G17) -> 106.16423 | H20: =H19*AVERAGE(H14,H17) -> 85.993359
B21: Loans and Notes Payables as a % of Long Term Debt | D21: ='Balance Sheet'!H65 -> 0.075997496 | E21: ='Balance Sheet'!I65 -> 0.075997496 | F21: ='Balance Sheet'!J65 -> 0.075997496 | G21: ='Balance Sheet'!K65 -> 0.075997496 | H21: ='Balance Sheet'!L65 -> 0.075997496
B23: Average Interest Rate | D23: 0.034 | E23: =D23 -> 0.034 | F23: =E23 -> 0.034 | G23: =F23 -> 0.034 | H23: =G23 -> 0.034
B24: Interest Expenses | D24: =D23*AVERAGE(D6,D9) -> 1409.362 | E24: =E23*AVERAGE(E6,E9) -> 1305.9627 | F24: =F23*AVERAGE(F6,F9) -> 1190.2497 | G24: =G23*AVERAGE(G6,G9) -> 1042.9118 | H24: =H23*AVERAGE(H6,H9) -> 860.69562
A25: # | B25: Total Long Term Debt / EBITDA | D25: ='Balance Sheet'!H64 -> 2.470343 | E25: ='Balance Sheet'!I64 -> 2.1027573 | F25: ='Balance Sheet'!J64 -> 1.7351715 | G25: ='Balance Sheet'!K64 -> 1.3675858 | H25: ='Balance Sheet'!L64 -> 1

Sheet Cost of Capital>

Sheet Cost of Debt
A2: # | B2: Calculation of Cost of Debt
B5: As per Long Term Bond in Coca-Cola 10K 2024
B6: Name of Bond | C6: Coca-Cola Company 7.375% 29-JUL-2093
B7: Symbol | C7: KO.GC
B8: Cost of Debt | C8: =C21*(1-C9) -> 0.043431854
B9: Marginal Tax Rate 1 | C9: =Valuation!D5 -> 0.27
B10: Yield of Coca-Cola Bond -
B11: Frequency | C11: Semi-Annual
B12: FV | C12: 1000
B13: CMP | C13: 1.23597
B14: CMP Amount | C14: =C13*C12 -> 1235.97
B15: Redemption | C15: 70704
B16: Valuation Date | C16: 45858
B17: Time to Maturity | C17: =(YEARFRAC(C16,C15,))*2 -> 136.05
B18: Coupon | C18: =7.38%/2 -> 0.0369
B19: Coupon Amount | C19: =(C18*C12) -> 36.9
B20: YTM | C20: =RATE(C17,C19,-C14,C12,) -> 0.029747845
B21: YTM (Annualised) | C21: =C20*2 -> 0.05949569
B24: Notes -
A25: # | B25: 1. Tax rate taken according to KPMG Corporate Tax Rate Table

Sheet Cost of Equity
A2: # | B2: Calculation of Cost of Equity (CAPM)
B5: Risk free rate of returns 1 | C5: 0.04416
B7: Date 2 | C7: Year | D7: Index Value
B8: 31048 | C8: 1985 | D8: 179.63
B9: 45857 | C9: 2025 | D9: 6296.79
B10: Total Years | C10: =YEARFRAC(B8,B9) -> 40.55
B12: CAGR | C12: =(D9/D8)^(1/C10)-1 -> 0.091678372
B13: Bottom up Beta | C13: =F29 -> 0.44407787
B14: Cost of Equity (Ke) | C14: =C5+(C12-C5)*C13 -> 0.065261857
B17: Name | C17: Regression Beta | D17: Market Cap | E17: Net Debt | F17: Total Capital | G17: Unlevered Beta
B18: Target Firm
B19: Coca Cola | C19: =H36 -> 0.42653283 | D19: 268203 | E19: 29951 | F19: =SUM(D19:E19) -> 298154 | G19: =C19/(1+((E19*(1-Valuation!$D$5))/D19)) -> 0.39438232
B21: Comps -
B22: PepsiCo, Inc. | C22: =K36 -> 0.37732384 | D22: 212201 | E22: 35040 | F22: =SUM(D22:E22) -> 247241 | G22: =C22/(1+((E22*(1-Valuation!$D$5))/D22)) -> 0.33673323
B23: Monster Beverage Corporation | C23: =N36 -> 0.56391026 | D23: 51116 | E23: 0 | F23: =SUM(D23:E23) -> 51116 | G23: =C23/(1+((E23*(1-Valuation!$D$5))/D23)) -> 0.56391026
B24: KEURIG DR PEPPER INC | C24: =Q36 -> 0.414647 | D24: 43569 | E24: 15044 | F24: =SUM(D24:E24) -> 58613 | G24: =C24/(1+((E24*(1-Valuation!$D$5))/D24)) -> 0.33117111
F25: Average Unlevered Beta | G25: =AVERAGE(G22:G24) -> 0.41060487
B27: Relevered Beta -
B28: Average Unlevered Beta of Comps | C28: Market Cap | D28: Net Debt | E28: Total Capital | F28: Relevered Beta
B29: =G25 -> 0.41060487 | C29: =D19 -> 268203 | D29: =E19 -> 29951 | E29: =F19 -> 298154 | F29: =B29*(1+((D29*(1-Valuation!D5)/'Cost of Equity'!C29))) -> 0.44407787
B31: Notes -
B32: 1. Risk free return taken as the 10 year US treasury yield
A33: # | B33: 2. Valuation date is on 19-07-2025
E35: S&P 500 | H35: Coca Cola | K35: PepsiCo, Inc. | N35: Monster Beverage Corporation | Q35: KEURIG DR PEPPER INC
B36: Regression Beta | E36: =SLOPE(F38:F297,$F$38:$F$297) -> 1 | H36: =SLOPE(I38:I297,$F$38:$F$297) -> 0.42653283 | K36: =SLOPE(L38:L297,$F$38:$F$297) -> 0.37732384 | N36: =SLOPE(O38:O297,$F$38:$F$297) -> 0.56391026 | Q36: =SLOPE(R38:R297,$F$38:$F$297) -> 0.414647
C37: Date | E37: Price | F37: Returns | H37: Price | I37: Returns | K37: Price | L37: Returns | N37: Price | O37: Returns | Q37: Price | R37: Returns
C38: 07/13/2025 | E38: 6296.79 | F38: =E38/E39-1 -> 0.0059171692 | H38: 69.85 | I38: =H38/H39-1 -> -0.00028624589 | K38: 143.27 | L38: =K38/K39-1 -> 0.059219281 | N38: 59 | O38: =N38/N39-1 -> 0.0028896821 | Q38: 33.54 | R38: =Q38/Q39-1 -> 0.001492983
C39: 45815 | E39: 6259.75 | F39: =E39/E40-1 -> -0.0031213422 | H39: 69.87 | I39: =H39/H40-1 -> -0.020742817 | K39: 135.26 | L39: =K39/K40-1 -> -0.00088639385 | N39: 58.83 | O39: =N39/N40-1 -> -0.067374762 | Q39: 33.49 | R39: =Q39/Q40-1 -> -0.0088783664
C40: 06/29/2025 | E40: 6279.35 | F40: =E40/E41-1 -> 0.017216717 | H40: 71.35 | I40: =H40/H41-1 -> 0.014503057 | K40: 135.38 | L40: =K40/K41-1 -> 0.033119658 | N40: 63.08 | O40: =N40/N41-1 -> 0.022200616 | Q40: 33.79 | R40: =Q40/Q41-1 -> 0.028614916
C41: 06/22/2025 | E41: 6173.07 | F41: =E41/E42-1 -> 0.034389327 | H41: 70.33 | I41: =H41/H42-1 -> 0.021644393 | K41: 131.04 | L41: =K41/K42-1 -> 0.015263036 | N41: 61.71 | O41: =N41/N42-1 -> -0.021873514 | Q41: 32.85 | R41: =Q41/Q42-1 -> -0.02173913
C42: 06/15/2025 | E42: 5967.84 | F42: =E42/E43-1 -> -0.0015275298 | H42: 68.84 | I42: =H42/H43-1 -> -0.030695579 | K42: 129.07 | L42: =K42/K43-1 -> -0.013603363 | N42: 63.09 | O42: =N42/N43-1 -> 0.00047573739 | Q42: 33.58 | R42: =Q42/Q43-1 -> 0.016959419
C43: 45875 | E43: 5976.97 | F43: =E43/E44-1 -> -0.0038980994 | H43: 71.02 | I43: =H43/H44-1 -> -0.0046250876 | K43: 130.85 | L43: =K43/K44-1 -> 0.006306237 | N43: 63.06 | O43: =N43/N44-1 -> -0.0055196341 | Q43: 33.02 | R43: =Q43/Q44-1 -> 0.0076289289
C44: 45663 | E44: 6000.36 | F44: =E44/E45-1 -> 0.014999095 | H44: 71.35 | I44: =H44/H45-1 -> -0.010402219 | K44: 130.03 | L44: =K44/K45-1 -> -0.010802587 | N44: 63.41 | O44: =N44/N45-1 -> -0.008444097 | Q44: 32.77 | R44: =Q44/Q45-1 -> -0.026730027
C45: 05/25/2025 | E45: 5911.69 | F45: =E45/E46-1 -> 0.018761568 | H45: 72.1 | I45: =H45/H46-1 -> 0.0045980215 | K45: 131.45 | L45: =K45/K46-1 -> 0.016313592 | N45: 63.95 | O45: =N45/N46-1 -> 0.0093118687 | Q45: 33.67 | R45: =Q45/Q46-1 -> 0.022782503
C46: 05/18/2025 | E46: 5802.82 | F46: =E46/E47-1 -> -0.026107768 | H46: 71.77 | I46: =H46/H47-1 -> -0.0031944444 | K46: 129.34 | L46: =K46/K47-1 -> -0.020003031 | N46: 63.36 | O46: =N46/N47-1 -> 0.0079541839 | Q46: 32.92 | R46: =Q46/Q47-1 -> -0.026611473
C47: 45966 | E47: 5958.38 | F47: =E47/E48-1 -> 0.052734054 | H47: 72 | I47: =H47/H48-1 -> 0.020986954 | K47: 131.98 | L47: =K47/K48-1 -> 0.011806194 | N47: 62.86 | O47: =N47/N48-1 -> 0.030491803 | Q47: 33.82 | R47: =Q47/Q48-1 -> 0.0083482409
C48: 45752 | E48: 5659.91 | F48: =E48/E49-1 -> -0.0047057417 | H48: 70.52 | I48: =H48/H49-1 -> -0.01577111 | K48: 130.44 | L48: =K48/K49-1 -> -0.024747664 | N48: 61 | O48: =N48/N49-1 -> 0.01582015 | Q48: 33.54 | R48: =Q48/Q49-1 -> -0.025283348
C49: 04/27/2025 | E49: 5686.67 | F49: =E49/E50-1 -> 0.029222419 | H49: 71.65 | I49: =H49/H50-1 -> -0.0036156306 | K49: 133.75 | L49: =K49/K50-1 -> 0.0027740291 | N49: 60.05 | O49: =N49/N50-1 -> 0.023521391 | Q49: 34.41 | R49: =Q49/Q50-1 -> 0.00029069767
C50: 04/20/2025 | E50: 5525.21 | F50: =E50/E51-1 -> 0.045906449 | H50: 71.91 | I50: =H50/H51-1 -> -0.014931507 | K50: 133.38 | L50: =K50/K51-1 -> -0.066227947 | N50: 58.67 | O50: =N50/N51-1 -> 0.0044512926 | Q50: 34.4 | R50: =Q50/Q51-1 -> -0.028248588
C51: 04/13/2025 | E51: 5282.7 | F51: =E51/E52-1 -> -0.01503908 | H51: 73 | I51: =H51/H52-1 -> 0.02197956 | K51: 142.84 | L51: =K51/K52-1 -> -0.011008793 | N51: 58.41 | O51: =N51/N52-1 -> 0.0044711952 | Q51: 35.4 | R51: =Q51/Q52-1 -> 0.0068259386
...

Sheet DCF>

Sheet Valuation
A2: # | B2: Particulars | C2: Unit | D2: Forecast
D3: 2025 | E3: =D3+1 -> 2026 | F3: =E3+1 -> 2027 | G3: =F3+1 -> 2028 | H3: =G3+1 -> 2029
B4: EBIT | D4: ='P&L'!H22 -> 15012.967 | E4: ='P&L'!I22 -> 16406.574 | F4: ='P&L'!J22 -> 17857.633 | G4: ='P&L'!K22 -> 19432.805 | H4: ='P&L'!L22 -> 21068.247
B5: Tax Rate 1 | D5: 0.27 | E5: =D5 -> 0.27 | F5: =E5 -> 0.27 | G5: =F5 -> 0.27 | H5: =G5 -> 0.27
B6: Less: Incomes Taxes | D6: =D5*D4 -> 4053.5012 | E6: =E5*E4 -> 4429.7751 | F6: =F5*F4 -> 4821.5608 | G6: =G5*G4 -> 5246.8574 | H6: =H5*H4 -> 5688.4267
B7: NOPAT | D7: =D4-D6 -> 10959.466 | E7: =E4-E6 -> 11976.799 | F7: =F4-F6 -> 13036.072 | G7: =G4-G6 -> 14185.948 | H7: =H4-H6 -> 15379.82
B8: Add: D&A | D8: =CapEx!H19 -> 1130.8021 | E8: =CapEx!I19 -> 1161.1629 | F8: =CapEx!J19 -> 1203.3066 | G8: =CapEx!K19 -> 1241.4044 | H8: =CapEx!L19 -> 1287.1522
B9: Changes in WC | D9: =SUM(CFS!D17:D21) -> -2949.7271 | E9: =SUM(CFS!E17:E21) -> 969.12126 | F9: =SUM(CFS!F17:F21) -> 1042.1069 | G9: =SUM(CFS!G17:G21) -> 1134.7923 | H9: =SUM(CFS!H17:H21) -> 1197.1288
B10: Less: CapEx | D10: =CapEx!H7 -> 832.49001 | E10: =CapEx!I7 -> 814.54187 | F10: =CapEx!J7 -> 810.3691 | G10: =CapEx!K7 -> 886.39859 | H10: =CapEx!L7 -> 879.67146
B11: FCFF | D11: =D7+D8+D9-D10 -> 8308.0513 | E11: =E7+E8+E9-E10 -> 13292.542 | F11: =F7+F8+F9-F10 -> 14471.116 | G11: =G7+G8+G9-G10 -> 15675.746 | H11: =H7+H8+H9-H10 -> 16984.43
B13: Terminal Value | H13: =(H11*(1+D17))/($D$18-$D$17) -> 497876.46
B14: Total Cash Flow | D14: =D11 -> 8308.0513 | E14: =E11 -> 13292.542 | F14: =F11 -> 14471.116 | G14: =G11 -> 15675.746 | H14: =H11+H13 -> 514860.89
B15: Mid Year Convention | D15: 0.5 | E15: =D15+1 -> 1.5 | F15: =E15+1 -> 2.5 | G15: =F15+1 -> 3.5 | H15: =G15+1 -> 4.5
B16: PV of Cashflows | D16: =D14/((1+$D$18)^D15) -> 8057.8366 | E16: =E14/((1+$D$18)^E15) -> 12127.349 | F16: =F14/((1+$D$18)^F15) -> 12419.339 | G16: =G14/((1+$D$18)^G15) -> 12655.031 | H16: =H14/((1+$D$18)^H15) -> 390988.05
B17: GDP Growth (US) | D17: 0.028
B18: WACC | D18: ='Cost of Equity'!C14*('Cost of Equity'!D19/'Cost of Equity'!F19)+'Cost of Debt'!C8*('Cost of Equity'!E19/'Cost of Equity'!F19) -> 0.063068929 | H18: WACC
B19: Value of Firm | D19: =SUM(D16:H16) -> 436247.61 | H19: GDP Growth (US) | I19: =D25 -> 98.264262 | J19: 0.043 | K19: 0.053 | L19: 0.06307 | M19: 0.073 | N19: 0.083
B20: Less: Value of debt | D20: =SUM('Balance Sheet'!G25:G26,'Balance Sheet'!G29) -> 44522 | I20: 0.008 | J20: 105.13965 | K20: 80.896931 | L20: 65.392657 | M20: 54.817024 | N20: 47.004317
B21: Add:Cash and cash equivalents | D21: =SUM('Balance Sheet'!G6:G7) -> 12848 | I21: 0.018 | J21: 143.91575 | K21: 101.73164 | L21: 78.180523 | M21: 63.410961 | N21: 53.105204
B22: Add: Investments | D22: =SUM('Balance Sheet'!G9,'Balance Sheet'!G14,'Balance Sheet'!G41) -> 19928 | I22: 0.028 | J22: 234.39331 | K22: 139.23411 | L22: 98.261155 | M22: 75.824425 | N22: 61.424596
B23: Value of Equity | D23: =D19-D20+D21+D22 -> 424501.61 | I23: 0.038 | J23: 686.78111 | K23: 226.73987 | L23: 134.36144 | M23: 95.331297 | N23: 73.441495
B24: Shares Outstanding | D24: ='P&L'!G49 -> 4320 | I24: 0.04 | J24: 1139.1689 | K24: 260.39593 | L24: 145.33705 | M24: 100.65135 | N24: 76.515586
B25: FV/Share | D25: =D23/D24 -> 98.264262
B27: Notes -
B28: 1. Tax rate taken according to KPMG Corporate Tax Rate Table
